Workbook

Sheet Datos
A1: Resultados de la simulación (81 escenarios)
A2: Tamaño del vector clave = 142, número de pasadas = 5 (mismos valores del archivo de ejemplo).
A4: Escenario | B4: Matriz | C4: Tamaño página | D4: Páginas virtuales (NP) | E4: Marcos | F4: Política | G4: Referencias (NR) | H4: Fallas de página | I4: Accesos exitosos | J4: Tasa de fallas | K4: Tiempo total (s)
A5: 1 | B5: 8x8 | C5: 64 | D5: 4 | E5: 4 | F5: FIFO | G5: 1920 | H5: 2 | I5: =G5-H5 -> 1918 | J5: =H5/G5 -> 0.0010416667 | K5: =G5*0.0000001+H5*0.008 -> 0.016192
A6: 2 | B6: 8x8 | C6: 64 | D6: 4 | E6: 4 | F6: FIFOModified | G6: 1920 | H6: 2 | I6: =G6-H6 -> 1918 | J6: =H6/G6 -> 0.0010416667 | K6: =G6*0.0000001+H6*0.008 -> 0.016192
A7: 3 | B7: 8x8 | C7: 64 | D7: 4 | E7: 4 | F7: LRU | G7: 1920 | H7: 2 | I7: =G7-H7 -> 1918 | J7: =H7/G7 -> 0.0010416667 | K7: =G7*0.0000001+H7*0.008 -> 0.016192
A8: 4 | B8: 8x8 | C8: 64 | D8: 4 | E8: 8 | F8: FIFO | G8: 1920 | H8: 2 | I8: =G8-H8 -> 1918 | J8: =H8/G8 -> 0.0010416667 | K8: =G8*0.0000001+H8*0.008 -> 0.016192
A9: 5 | B9: 8x8 | C9: 64 | D9: 4 | E9: 8 | F9: FIFOModified | G9: 1920 | H9: 2 | I9: =G9-H9 -> 1918 | J9: =H9/G9 -> 0.0010416667 | K9: =G9*0.0000001+H9*0.008 -> 0.016192
A10: 6 | B10: 8x8 | C10: 64 | D10: 4 | E10: 8 | F10: LRU | G10: 1920 | H10: 2 | I10: =G10-H10 -> 1918 | J10: =H10/G10 -> 0.0010416667 | K10: =G10*0.0000001+H10*0.008 -> 0.016192
A11: 7 | B11: 8x8 | C11: 64 | D11: 4 | E11: 16 | F11: FIFO | G11: 1920 | H11: 2 | I11: =G11-H11 -> 1918 | J11: =H11/G11 -> 0.0010416667 | K11: =G11*0.0000001+H11*0.008 -> 0.016192
A12: 8 | B12: 8x8 | C12: 64 | D12: 4 | E12: 16 | F12: FIFOModified | G12: 1920 | H12: 2 | I12: =G12-H12 -> 1918 | J12: =H12/G12 -> 0.0010416667 | K12: =G12*0.0000001+H12*0.008 -> 0.016192
A13: 9 | B13: 8x8 | C13: 64 | D13: 4 | E13: 16 | F13: LRU | G13: 1920 | H13: 2 | I13: =G13-H13 -> 1918 | J13: =H13/G13 -> 0.0010416667 | K13: =G13*0.0000001+H13*0.008 -> 0.016192
A14: 10 | B14: 8x8 | C14: 256 | D14: 1 | E14: 4 | F14: FIFO | G14: 1920 | H14: 1 | I14: =G14-H14 -> 1919 | J14: =H14/G14 -> 0.00052083333 | K14: =G14*0.0000001+H14*0.008 -> 0.008192
A15: 11 | B15: 8x8 | C15: 256 | D15: 1 | E15: 4 | F15: FIFOModified | G15: 1920 | H15: 1 | I15: =G15-H15 -> 1919 | J15: =H15/G15 -> 0.00052083333 | K15: =G15*0.0000001+H15*0.008 -> 0.008192
A16: 12 | B16: 8x8 | C16: 256 | D16: 1 | E16: 4 | F16: LRU | G16: 1920 | H16: 1 | I16: =G16-H16 -> 1919 | J16: =H16/G16 -> 0.00052083333 | K16: =G16*0.0000001+H16*0.008 -> 0.008192
... A85: 81 | B85: 128x128 | C85: 1024 | D85: 17 | E85: 16 | F85: LRU | G85: 491520 | H85: 10321 | I85: =G85-H85 -> 481199 | J85: =H85/G85 -> 0.020998128 | K85: =G85*0.0000001+H85*0.008 -> 82.617152

Sheet Graficas
A1: Fallas de página por número de marcos y política (una gráfica por matriz y tamaño de página)
A3: Matriz: | B3: 8x8 | C3: Página (B): | D3: 64
A4: Marcos | B4: FIFO | C4: FIFOModified | D4: LRU
A5: 4 | B5: =Datos!H5 -> 2 | C5: =Datos!H6 -> 2 | D5: =Datos!H7 -> 2
A6: 8 | B6: =Datos!H8 -> 2 | C6: =Datos!H9 -> 2 | D6: =Datos!H10 -> 2
A7: 16 | B7: =Datos!H11 -> 2 | C7: =Datos!H12 -> 2 | D7: =Datos!H13 -> 2
A19: Matriz: | B19: 8x8 | C19: Página (B): | D19: 256
A20: Marcos | B20: FIFO | C20: FIFOModified | D20: LRU
A21: 4 | B21: =Datos!H14 -> 1 | C21: =Datos!H15 -> 1 | D21: =Datos!H16 -> 1
A22: 8 | B22: =Datos!H17 -> 1 | C22: =Datos!H18 -> 1 | D22: =Datos!H19 -> 1
A23: 16 | B23: =Datos!H20 -> 1 | C23: =Datos!H21 -> 1 | D23: =Datos!H22 -> 1
A35: Matriz: | B35: 8x8 | C35: Página (B): | D35: 1024
A36: Marcos | B36: FIFO | C36: FIFOModified | D36: LRU
A37: 4 | B37: =Datos!H23 -> 1 | C37: =Datos!H24 -> 1 | D37: =Datos!H25 -> 1
A38: 8 | B38: =Datos!H26 -> 1 | C38: =Datos!H27 -> 1 | D38: =Datos!H28 -> 1
A39: 16 | B39: =Datos!H29 -> 1 | C39: =Datos!H30 -> 1 | D39: =Datos!H31 -> 1
A51: Matriz: | B51: 16x16 | C51: Página (B): | D51: 64
A52: Marcos | B52: FIFO | C52: FIFOModified | D52: LRU
A53: 4 | B53: =Datos!H32 -> 425 | C53: =Datos!H33 -> 341 | D53: =Datos!H34 -> 341
A54: 8 | B54: =Datos!H35 -> 5 | C54: =Datos!H36 -> 5 | D54: =Datos!H37 -> 5
A55: 16 | B55: =Datos!H38 -> 5 | C55: =Datos!H39 -> 5 | D55: =Datos!H40 -> 5
A67: Matriz: | B67: 16x16 | C67: Página (B): | D67: 256
A68: Marcos | B68: FIFO | C68: FIFOModified | D68: LRU
A69: 4 | B69: =Datos!H41 -> 2 | C69: =Datos!H42 -> 2 | D69: =Datos!H43 -> 2
A70: 8 | B70: =Datos!H44 -> 2 | C70: =Datos!H45 -> 2 | D70: =Datos!H46 -> 2
A71: 16 | B71: =Datos!H47 -> 2 | C71: =Datos!H48 -> 2 | D71: =Datos!H49 -> 2
A83: Matriz: | B83: 16x16 | C83: Página (B): | D83: 1024
A84: Marcos | B84: FIFO | C84: FIFOModified | D84: LRU
A85: 4 | B85: =Datos!H50 -> 1 | C85: =Datos!H51 -> 1 | D85: =Datos!H52 -> 1
A86: 8 | B86: =Datos!H53 -> 1 | C86: =Datos!H54 -> 1 | D86: =Datos!H55 -> 1
A87: 16 | B87: =Datos!H56 -> 1 | C87: =Datos!H57 -> 1 | D87: =Datos!H58 -> 1
A99: Matriz: | B99: 128x128 | C99: Página (B): | D99: 64
A100: Marcos | B100: FIFO | C100: FIFOModified | D100: LRU
A101: 4 | B101: =Datos!H59 -> 104320 | C101: =Datos!H60 -> 85760 | D101: =Datos!H61 -> 85760
A102: 8 | B102: =Datos!H62 -> 93760 | C102: =Datos!H63 -> 84481 | D102: =Datos!H64 -> 84481
A103: 16 | B103: =Datos!H65 -> 88480 | C103: =Datos!H66 -> 84481 | D103: =Datos!H67 -> 84481
A115: Matriz: | B115: 128x128 | C115: Página (B): | D115: 256
A116: Marcos | B116: FIFO | C116: FIFOModified | D116: LRU
A117: 4 | B117: =Datos!H68 -> 51600 | C117: =Datos!H69 -> 41281 | D117: =Datos!H70 -> 41281
A118: 8 | B118: =Datos!H71 -> 46440 | C118: =Datos!H72 -> 41281 | D118: =Datos!H73 -> 41281
...
